Workbook

Sheet 使用說明
A1: 溫室土耕小番茄 種植工作計畫與排程表
A2: 給農場管理者派工、排程、檢查與紀錄使用｜資料彙整日期:2026-09
A4: 適用範圍 | B4: 溫室(網室)內土耕、滴灌、雙幹整枝之小果番茄(如玉女等不停心型品種)。預設作期為平地秋冬作:9–11月定植、隔年1–5月為產期高峰(S4)。
A5: 使用步驟 1 | B5: 到「參數與用量計算」只改黃底藍字的格子:定植日期、面積、畦距、株距、作期週數、施肥目標等。其他格子為公式,會自動算出株數、訂苗數、最晚訂苗日、基肥與每次追肥量、黏紙與熊蜂箱數。
A6: 使用步驟 2 | B6: 「階段工作清單」:依定植日自動換算每項工作的預定日期。可在「負責人/狀態/完成日期」欄派工與追蹤(狀態有下拉選單)。
A7: 使用步驟 3 | B7: 「週曆排程」:從定植前8週到作期結束後,每週要做哪些工作一目了然(●=本週執行,★=關鍵節點)。可直接列印貼在工作站。
A8: 使用步驟 4 | B8: 「例行作業檢查表」:每日/每2天/每週/每3週/每月/每期作的固定工作與執行標準,每週列印一張簽核。
A9: 使用步驟 5 | B9: 「管理數值標準」「病蟲害監測防治」:溫濕度、土壤、肥料、灌溉、整枝、授粉、採收貯藏的數值標準與病蟲害判斷做法,每條都標註來源代碼(對照「資料來源」頁)。
A10: 使用步驟 6 | B10: 「紀錄_」開頭的6張表:依TGAP產銷履歷需要的紀錄格式設計(田間作業、施肥灌溉、病蟲害防治、溫濕度、生長量測、採收出貨),第一列灰底為填寫範例。
A11: 格式說明 | B11: 黃底藍字 = 可自行修改的輸入值;黑字 = 公式自動計算;灰底斜體 = 範例列(可刪除或覆寫)。
A12: 重要提醒 1 | B12: 國外數據多來自介質(岩棉/椰纖)高架栽培與大果品種,移用到國內土耕小番茄時請當作起始參考,依自家紀錄調整。表中已標註「國內/國外」。
A13: 重要提醒 2 | B13: 「預估首採週」為估計值(預設定植後第11週),實際受品種、定植期與溫度影響,請於第一穗果轉色時修正參數,排程會自動更新。
A14: 重要提醒 3 | B14: 農藥登記內容會變動,本表不列固定藥劑倍數;用藥前一律至「農藥資訊服務網」(S22)查詢番茄現行登記藥劑、稀釋倍數與安全採收期,並記錄於「紀錄_病蟲害防治」。
A15: 重要提醒 4 | B15: 施肥量以TGAP番茄建議三要素總量換算(S2),未扣除堆肥所含養分;若土壤檢測磷鉀偏高,請依改良場土壤診斷建議減量。
A17: 輸入格範例 | B17: 2026/10/15
A18: 公式格範例 | B18: ="自動計算結果" -> 自動計算結果

Sheet 參數與用量計算
A1: 參數與用量計算
A2: 只修改黃底藍字格;其餘自動計算
A3: 項目 | B3: 數值 | C3: 單位 | D3: 說明 / 來源
A4: 定植日期 | B4: 46310 | C4: 日期 | D4: 暫定;平地秋冬作多於9–11月定植(S4)
A5: 種植區面積 | B5: 1000 | C5: m² | D5: 1分地≈970 m²;此處填實際作畦區面積(含畦溝)
A6: 畦距(畦中心到中心) | B6: 1.5 | C6: m | D6: 春秋作行距75–150 cm(S1)
A7: 每畦種植行數 | B7: 1 | C7: 行 | D7: 單行植或雙行植
A8: 株距 | B8: 0.6 | C8: m | D8: 春秋作株距60 cm;夏作45 cm(S1)
A9: 整枝幹數 | B9: 2 | C9: 幹/株 | D9: 雙幹整枝:留第一花序下側枝(S1)
A10: 備苗比例 | B10: 0.1 | C10: % | D10: 假設值:供補植用
A11: 育苗場育苗期(參考) | B11: 5 | C11: 週 | D11: 穴盤苗育苗約4–6週(S12);用來推估育苗場需播種的日期
A12: 穴盤規格 | B12: 128 | C12: 格/盤 | D12: 秋冬作128格、夏作72格(S1)
A13: 訂苗提前週數 | B13: 2 | C13: 週 | D13: 育苗場要求至少定植前2週下訂(農場提供);不可小於2
A14: 預估首花週 | B14: 3 | C14: 定植後第幾週 | D14: 假設值:第一花序開花,開始授粉
A15: 追肥起始週 | B15: 4 | C15: 定植後第幾週 | D15: 首次追肥於定植後20–30天(S1)
... A31: 黏紙每張涵蓋面積 | B31: 93 | C31: m² | D31: 每1,000 ft²(≈93 m²)1張(S19)
A33: ▍ 自動計算:株數與訂苗
A34: 定植株數 | B34: =ROUNDDOWN(B5/B6*B7/B8,0) -> 1111 | C34: 株 | D34: 面積÷畦距×行數÷株距
A35: 總幹數 | B35: =B34*B9 -> 2222 | C35: 幹
A36: 每幹佔面積 | B36: =B5/B35 -> 0.450045 | C36: m²/幹 | D36: =IF(AND(B36>=0.33,B36<=0.56),"✔ 在國外建議3.5–6 ft²(0.33–0.56 m²)/幹範圍內(S13)","⚠ 超出0.33–0.56 m²/幹參考範圍,密度過高易病害、過低減產(S13)") -> ✔ 在國外建議3.5–6 ft²(0.33–0.56 m²)/幹範圍內(S13)
A37: 訂苗數 | B37: =ROUNDUP(B34*(1+B10),0) -> 1223 | C37: 株 | D37: 含備苗;訂苗規格:苗齡四本葉(4–6葉)、株高約10–15 cm(S1、S2、S12)
A38: 最晚訂苗日 | B38: =B4-MAX(B13,2)*7 -> 46296 | C38: 日期 | D38: =IF(B38<TODAY(),"⚠ 最晚訂苗日已過,請立即聯絡育苗場或延後定植日","距最晚訂苗日還有"&(B38-TODAY())&"天") -> 距最晚訂苗日還有15天
A39: 穴盤數 | B39: =ROUNDUP(B37/B12,0) -> 10 | C39: 盤
A40: 育苗場推估播種日 | B40: =B4-B11*7 -> 46275 | C40: 日期 | D40: =IF(B40<TODAY(),"此日已過:下訂時請確認育苗場有該品種現成苗(嫁接苗通常需更長時間)","") -> 此日已過:下訂時請確認育苗場有該品種現成苗(嫁接苗通常需更長時間)
A41: 到苗驗收日 | B41: =B4 -> 46310 | C41: 日期 | D41: 到苗當天驗收後定植(見工作A11)
A42: 首採日(估) | B42: =B4+B18*7 -> 46387 | C42: 日期
A43: 摘心日 | B43: =B4+(B19-6)*7 -> 46478 | C43: 日期 | D43: 作期結束前6週摘除頂芽(S12)
A44: 末採日 | B44: =B4+B19*7 -> 46520 | C44: 日期
A45: 黃色黏紙張數(監測) | B45: =ROUNDUP(B5/B31,0) -> 11 | C45: 張 | D45: 放在通風口、門口、周邊,高度與作物冠層齊(S19、S8)
A46: 熊蜂箱數(下限) | B46: =ROUNDUP(B5/1000*1,0) -> 1 | C46: 箱 | D46: 每分地1–2箱(S4)
A47: 熊蜂箱數(上限) | B47: =ROUNDUP(B5/1000*2,0) -> 2 | C47: 箱
A49: ▍ 自動計算:施肥量(本場面積)
A50: 項目 | B50: N (kg) | C50: P₂O₅ (kg) | D50: K₂O (kg)
A51: 全期總量 | B51: =B20*$B$5/10000 -> 22.5 | C51: =B21*$B$5/10000 -> 17.5 | D51: =B22*$B$5/10000 -> 15
A52: 基肥元素量 | B52: =B51*B23 -> 4.05 | C52: =C51 -> 17.5 | D52: =D51*B24 -> 2.7
A53: 每次追肥元素量 | B53: =B51*(1-B23)/B17 -> 2.6357143 | C53: 0 | D53: =D51*(1-B24)/B17 -> 1.7571429
A54: 每次追肥佔總量% | B54: =(1-B23)/B17 -> 0.11714286 | D54: =(1-B24)/B17 -> 0.11714286
A55: 檢核 | B55: =IF(AND(B54>=0.1,B54<=0.15,D54>=0.1,D54<=0.15),"✔ 每次追肥N、K各佔10–15%,符合TGAP(S2)","⚠ 每次追肥比例不在10–15%,請調整追肥次數或基肥比例") -> ✔ 每次追肥N、K各佔10–15%,符合TGAP(S2)
A57: ▍ 換算成肥料產品量(kg)
A58: 肥料 | B58: 基肥 (kg) | C58: 每次追肥 (kg) | D58: 說明
...

Sheet 階段工作清單
A1: 階段工作清單(依定植日自動排日期)
A2: 週次:定植當週=0,負數為定植前。狀態可下拉選擇。
A3: 編號 | B3: 階段 | C3: 起始週次 | D3: 預定日期 | E3: 頻率 | F3: 工作項目 | G3: 具體做法與數值標準 | H3: 完成判定/檢查點 | I3: 紀錄表 | J3: 來源 | K3: 負責人 | L3: 狀態 | M3: 完成日期 | N3: 逾期提醒
A4: A01 | B4: 作前準備 | C4: -8 | D4: =參數與用量計算!$B$4+C4*7 -> 46254 | E4: 一次 | F4: 前作清園 | G4: 前作植株、殘根、落果、舊黏紙全部清出溫室並裝袋帶離園區;清除棚內與周邊雜草。 | H4: 地面無殘株落果 | I4: 紀錄_田間作業 | J4: S8 | L4: 未開始 | N4: =IF(L4="完成","",IF(D4<TODAY(),"⚠ 已過預定日",IF(D4-TODAY()<=7,"本週到期",""))) -> ⚠ 已過預定日
A5: A02 | B5: 作前準備 | C5: -8 | D5: =參數與用量計算!$B$4+C5*7 -> 46254 | E5: 每期作 | F5: 土壤採樣送驗 | G5: 依送驗單位規定採樣,檢驗pH、EC、有機質、磷、鉀、鈣、鎂。TGAP標準:pH 5.6–7.0、EC不超過2.0 dS/m。 | H5: 取得檢驗報告並存檔 | I5: 紀錄_施肥灌溉 | J5: S2 | L5: 未開始 | N5: =IF(L5="完成","",IF(D5<TODAY(),"⚠ 已過預定日",IF(D5-TODAY()<=7,"本週到期",""))) -> ⚠ 已過預定日
A6: A03 | B6: 作前準備 | C6: -8 | D6: =參數與用量計算!$B$4+C6*7 -> 46254 | E6: 視需要 | F6: 鹽化/連作土壤改良 | G6: 若EC偏高:休閒期施稻草約1公噸/分地,或低養分纖維質堆肥10–20公噸/公頃,需1個月以上分解;排水不良田區於地表下60–80 cm埋設暗渠排水;以大量清水淋洗降低鹽分。 | H6: 複驗EC回到標準內 | I6: 紀錄_田間作業 | J6: S10、S2 | L6: 未開始 | N6: =IF(L6="完成","",IF(D6<TODAY(),"⚠ 已過預定日",IF(D6-TODAY()<=7,"本週到期",""))) -> ⚠ 已過預定日
A7: A04 | B7: 作前準備 | C7: -7 | D7: =參數與用量計算!$B$4+C7*7 -> 46261 | E7: 一次 | F7: 青枯病風險決策 | G7: 田區曾發生青枯病→改用茄子根砧(EG203、EG219、EG190)嫁接苗:自根苗罹病率80–100%,嫁接苗15%以下;或與水稻輪作;灌溉水不可流經病田。 | H7: 決定用自根苗或嫁接苗並下訂 | I7: 紀錄_田間作業 | J7: S6、S7 | L7: 未開始 | N7: =IF(L7="完成","",IF(D7<TODAY(),"⚠ 已過預定日",IF(D7-TODAY()<=7,"本週到期",""))) -> ⚠ 已過預定日
A8: A05 | B8: 作前準備 | C8: -6 | D8: =參數與用量計算!$B$4+C8*7 -> 46268 | E8: 一次 | F8: 溫室設施檢修 | G8: 防蟲網破洞修補、出入口檢查;側窗/捲揚、遮陰網、循環風扇試運轉(參考:9×30 m溫室配4台、每台≥1,600 cfm);滴灌管路試水,逐條檢查出水均勻、無堵塞漏水。 | H8: 設施檢查表全數合格 | I8: 紀錄_田間作業 | J8: S13 | L8: 未開始 | N8: =IF(L8="完成","",IF(D8<TODAY(),"⚠ 已過預定日",IF(D8-TODAY()<=7,"本週到期",""))) -> ⚠ 已過預定日
A9: A06 | B9: 作前準備 | C9: =-MAX(參數與用量計算!$B$13,2) -> -2 | D9: =參數與用量計算!$B$4+C9*7 -> 46296 | E9: 一次 | F9: 向育苗場訂苗 | G9: 最晚於定植前2週(參數表B38)下訂,數量見B37(含備苗)。訂單寫明:品種、苗齡四本葉(4–6葉)、株高約10–15 cm、秋冬作128格穴盤苗、育苗期以60目網隔離銀葉粉蝨;青枯病田須指定茄砧(EG203、EG219、EG190)嫁接苗(依A04決策)。下訂時確認到苗日,以及育苗場是否有現成苗。 | H9: 取得育苗場確認(品種、數量、規格、到苗日) | I9: 紀錄_田間作業 | J9: S1、S2、S12、S7 | L9: 未開始 | N9: =IF(L9="完成","",IF(D9<TODAY(),"⚠ 已過預定日",IF(D9-TODAY()<=7,"本週到期","")))
A10: A07 | B10: 作前準備 | C10: -3 | D10: =參數與用量計算!$B$4+C10*7 -> 46289 | E10: 一次 | F10: 基肥施用與整地 | G10: 依參數表B59–B63施用:堆肥、硼砂、全量磷肥,氮與鉀肥15–20%;均勻撒施後翻耕。 | H10: 施肥量與紀錄一致 | I10: 紀錄_施肥灌溉 | J10: S1、S2 | L10: 未開始 | N10: =IF(L10="完成","",IF(D10<TODAY(),"⚠ 已過預定日",IF(D10-TODAY()<=7,"本週到期","")))
A11: A08 | B11: 作前準備 | C11: -2 | D11: =參數與用量計算!$B$4+C11*7 -> 46296 | E11: 一次 | F11: 作畦、鋪滴灌 | G11: 依參數表畦距、行數作畦;鋪設滴灌帶,寬畦需3–4條滴帶才能整畦濕潤;通水確認畦面濕潤均勻。 | H11: 每畦濕潤帶連續無乾點 | I11: 紀錄_田間作業 | J11: S13 | L11: 未開始 | N11: =IF(L11="完成","",IF(D11<TODAY(),"⚠ 已過預定日",IF(D11-TODAY()<=7,"本週到期","")))
A12: A09 | B12: 作前準備 | C12: -1 | D12: =參數與用量計算!$B$4+C12*7 -> 46303 | E12: 一次 | F12: 架設吊線/支架 | G12: 吊線鋼線高度至少2.4 m(8 ft)以上,每株預留一條尼龍吊繩或支柱(雙幹則每幹一條)。 | H12: 吊繩數=總幹數(參數表B35) | I12: 紀錄_田間作業 | J12: S13 | L12: 未開始 | N12: =IF(L12="完成","",IF(D12<TODAY(),"⚠ 已過預定日",IF(D12-TODAY()<=7,"本週到期","")))
A13: A10 | B13: 作前準備 | C13: -1 | D13: =參數與用量計算!$B$4+C13*7 -> 46303 | E13: 一次 | F13: 懸掛監測黏紙 | G13: 黃色黏紙數量見參數表B45,放在通風口、門口與周邊,高度與作物冠層齊並隨植株升高;另掛藍色黏紙監測薊馬。 | H13: 黏紙已編號並標示位置圖 | I13: 紀錄_病蟲害防治 | J13: S19、S8 | L13: 未開始 | N13: =IF(L13="完成","",IF(D13<TODAY(),"⚠ 已過預定日",IF(D13-TODAY()<=7,"本週到期","")))
A14: A11 | B14: 定植緩苗 | C14: 0 | D14: =參數與用量計算!$B$4+C14*7 -> 46310 | E14: 到苗當天 | F14: 到苗驗收 | G14: 逐盤檢查:苗齡四本葉(4–6葉)、株高約10–15 cm、根團完整;剔除捲葉、黃化、矮化苗,不合格數量當場與育苗場確認補苗;記錄育苗場名稱、品種、批號、數量。 | H14: 不合格苗剔除並記錄 | I14: 紀錄_田間作業 | J14: S1、S2、S12 | L14: 未開始 | N14: =IF(L14="完成","",IF(D14<TODAY(),"⚠ 已過預定日",IF(D14-TODAY()<=7,"本週到期","")))
A15: B01 | B15: 定植緩苗 | C15: 0 | D15: =參數與用量計算!$B$4+C15*7 -> 46310 | E15: 一次 | F15: 定植 | G15: 依株距定植;定植前後充分灌水。可控溫溫室:定植後24°C維持1–2天,再每天降約1°C至19°C。嫁接苗嫁接口保持在土面以上。 | H15: 定植株數=參數表B34 | I15: 紀錄_田間作業 | J15: S17 | L15: 未開始 | N15: =IF(L15="完成","",IF(D15<TODAY(),"⚠ 已過預定日",IF(D15-TODAY()<=7,"本週到期","")))
A16: B02 | B16: 定植緩苗 | C16: 0 | D16: =參數與用量計算!$B$4+C16*7 -> 46310 | E16: 每日 | F16: 緩苗期灌溉 | G16: 參考農業部土耕滴灌試驗:生長初期每日滴灌2次、每次10分鐘;依滴帶出水量與土壤濕度(手握成團不滴水)調整。 | H16: 無萎凋、土壤不積水 | I16: 紀錄_施肥灌溉 | J16: S3、S13 | L16: 未開始 | N16: =IF(L16="完成","",IF(D16<TODAY(),"⚠ 已過預定日",IF(D16-TODAY()<=7,"本週到期","")))
A17: B03 | B17: 定植緩苗 | C17: 1 | D17: =參數與用量計算!$B$4+C17*7 -> 46317 | E17: 一次 | F17: 補植 | G17: 檢查缺株、病株(捲葉、萎凋),以備苗補植。 | H17: 全區無缺株 | I17: 紀錄_田間作業 | J17: — | L17: 未開始 | N17: =IF(L17="完成","",IF(D17<TODAY(),"⚠ 已過預定日",IF(D17-TODAY()<=7,"本週到期","")))
A18: B04 | B18: 定植緩苗 | C18: 1 | D18: =參數與用量計算!$B$4+C18*7 -> 46317 | E18: 每週 | F18: 誘引上架 | G18: 沿主莖約每25 cm(10吋)夾一個誘引夾;夾在兩片葉之間,不要夾在花序下方。 | H18: 生長點都在吊繩上 | I18: 紀錄_田間作業 | J18: S12、S14 | L18: 未開始 | N18: =IF(L18="完成","",IF(D18<TODAY(),"⚠ 已過預定日",IF(D18-TODAY()<=7,"本週到期","")))
A19: B05 | B19: 營養生長 | C19: 2 | D19: =參數與用量計算!$B$4+C19*7 -> 46324 | E19: 一次 | F19: 雙幹整枝定幹 | G19: 保留主幹及第一花序下方的側枝作為第二幹,其餘側芽全部摘除。 | H19: 每株2幹、無多餘側枝 | I19: 紀錄_田間作業 | J19: S1 | L19: 未開始 | N19: =IF(L19="完成","",IF(D19<TODAY(),"⚠ 已過預定日",IF(D19-TODAY()<=7,"本週到期","")))
A20: C01 | B20: 營養生長 | C20: 2 | D20: =參數與用量計算!$B$4+C20*7 -> 46324 | E20: 每週 | F20: 摘側芽 | G20: 至少每週一次;側芽長到5–7.5 cm(2–3吋)前摘除,乾脆折斷避免撕裂傷口,宜在晴天乾燥時段進行。 | H20: 巡查無超過7.5 cm側芽 | I20: 紀錄_田間作業 | J20: S12、S13 | L20: 未開始 | N20: =IF(L20="完成","",IF(D20<TODAY(),"⚠ 已過預定日",IF(D20-TODAY()<=7,"本週到期","")))
A21: C02 | B21: 開花著果 | C21: =參數與用量計算!$B$14 -> 3 | D21: =參數與用量計算!$B$4+C21*7 -> 46331 | E21: 每2天 | F21: 熊蜂授粉(方案一) | G21: 每分地放1–2箱(參數表B46–B47);蜂箱水平放置、顯眼、防凝結水,炎熱時遮陰;熊蜂活動溫度8–28°C(最高約32°C)。每2天在不同位置採20朵已閉合的花檢查咬痕,應全部有咬痕;每朵咬痕降到只剩1–2個時換新箱。 | H21: 20朵閉合花咬痕率100% | I21: 紀錄_溫濕度 | J21: S4、S18 | L21: 未開始 | N21: =IF(L21="完成","",IF(D21<TODAY(),"⚠ 已過預定日",IF(D21-TODAY()<=7,"本週到期","")))
A22: C03 | B22: 開花著果 | C22: =參數與用量計算!$B$14 -> 3 | D22: =參數與用量計算!$B$4+C22*7 -> 46331 | E22: 冬6–7天/夏4–5天 | F22: 生長調節劑著果(方案二) | G22: 花序有2–3朵花盛開時噴花:番茄多旺 20°C用100倍、30°C用250倍;或多結果朗 20°C用800倍、30°C用1200倍。施用頻率夏季約4–5天一次、冬季6–7天一次。使用前確認現行登記。 | H22: 每花序皆有處理紀錄 | I22: 紀錄_病蟲害防治 | J22: S1、S4、S22 | L22: 未開始 | N22: =IF(L22="完成","",IF(D22<TODAY(),"⚠ 已過預定日",IF(D22-TODAY()<=7,"本週到期","")))
A23: C04 | B23: 開花著果 | C23: =參數與用量計算!$B$14 -> 3 | D23: =參數與用量計算!$B$4+C23*7 -> 46331 | E23: 每週3次 | F23: 振動授粉(方案三) | G23: 以電動振動器或搖動吊線振動花序,每週3次;陰濕天花粉釋放差時每天進行;相對濕度60–70%時效果最好。 | H23: 著果率持續上升 | I23: 紀錄_田間作業 | J23: S12、S13 | L23: 未開始 | N23: =IF(L23="完成","",IF(D23<TODAY(),"⚠ 已過預定日",IF(D23-TODAY()<=7,"本週到期","")))
A24: C05 | B24: 開花著果 | C24: =參數與用量計算!$B$15 -> 4 | D24: =參數與用量計算!$B$4+C24*7 -> 46338 | E24: 一次 | F24: 第1次追肥 | G24: 定植後20–30天、第一花序結果時;用量見參數表B53、C60–C61。之後依追肥日程表每3週一次。 | H24: 依量施用並記錄 | I24: 紀錄_施肥灌溉 | J24: S1、S2 | L24: 未開始 | N24: =IF(L24="完成","",IF(D24<TODAY(),"⚠ 已過預定日",IF(D24-TODAY()<=7,"本週到期","")))
A25: C06 | B25: 開花著果 | C25: =參數與用量計算!$B$14 -> 3 | D25: =參數與用量計算!$B$4+C25*7 -> 46331 | E25: 每週 | F25: 生長量測 | G25: 固定標記10株(平均分布在溫室南北、東西側與中間),每週量:莖徑(上週生長點位置)、生長點至最上開花花序距離、新開花序數、著果數。國外大果參考值:莖徑10–12 mm、花距13–18 cm;小果請以前3–4週數據建立自家基準。花距變短/莖變細=偏生殖生長;花距變長/莖變粗=偏營養生長。 | H25: 每週10株數據完整 | I25: 紀錄_生長量測 | J25: S15 | L25: 未開始 | N25: =IF(L25="完成","",IF(D25<TODAY(),"⚠ 已過預定日",IF(D25-TODAY()<=7,"本週到期","")))
A26: C07 | B26: 開花著果 | C26: =參數與用量計算!$B$14 -> 3 | D26: =參數與用量計算!$B$4+C26*7 -> 46331 | E26: 每週 | F26: 疏花疏果(依品種) | G26: 果穗過長或弱株:小果每穗留8–10果(或8–12果),每週一次。 | H26: 果穗留果數一致 | I26: 紀錄_田間作業 | J26: S12、S14 | L26: 未開始 | N26: =IF(L26="完成","",IF(D26<TODAY(),"⚠ 已過預定日",IF(D26-TODAY()<=7,"本週到期","")))
A27: C08 | B27: 開花著果 | C27: 6 | D27: =參數與用量計算!$B$4+C27*7 -> 46352 | E27: 每日 | F27: 盛花期濕度管理 | G27: 盛花期約定植後40–50天。相對濕度維持低於90%,日出後通風並開循環風扇,降低灰黴病、葉黴病。 | H27: 每日RH紀錄<90% | I27: 紀錄_溫濕度 | J27: S1、S13 | L27: 未開始 | N27: =IF(L27="完成","",IF(D27<TODAY(),"⚠ 已過預定日",IF(D27-TODAY()<=7,"本週到期","")))
A28: D01 | B28: 結果採收 | C28: =參數與用量計算!$B$18 -> 11 | D28: =參數與用量計算!$B$4+C28*7 -> 46387 | E28: 一次 | F28: 第1果房轉色→調整肥水 | G28: 參考農業部試驗:第1果房轉色期起滴灌改為每日1次、每次5分鐘(依土壤濕度調整);水溶肥由20-20-20改為高鉀15-20-25。結果期N:P₂O₅:K₂O約3:1:2(生育初期約6:1:4)。避免忽乾忽濕,以免裂果、尻腐。 | H28: 無裂果尻腐增加 | I28: 紀錄_施肥灌溉 | J28: S3、S2、S13 | L28: 未開始 | N28: =IF(L28="完成","",IF(D28<TODAY(),"⚠ 已過預定日",IF(D28-TODAY()<=7,"本週到期","")))
A29: D02 | B29: 結果採收 | C29: =參數與用量計算!$B$18 -> 11 | D29: =參數與用量計算!$B$4+C29*7 -> 46387 | E29: 每週 | F29: 摘下位葉 | G29: 採收完的果房以下葉片全部摘除,並多摘果房上方1片;維持約1.5–1.8 m(5–6 ft)葉幕。摘下的葉片帶出溫室。 | H29: 果房下方無老葉 | I29: 紀錄_田間作業 | J29: S14、S12 | L29: 未開始 | N29: =IF(L29="完成","",IF(D29<TODAY(),"⚠ 已過預定日",IF(D29-TODAY()<=7,"本週到期","")))
A30: D03 | B30: 結果採收 | C30: =參數與用量計算!$B$18 -> 11 | D30: =參數與用量計算!$B$4+C30*7 -> 46387 | E30: 每週(選用) | F30: 落蔓(採吊蔓時) | G30: 採吊繩落蔓系統時,小果番茄每週約放下1.5圈吊繩,讓生長點維持在工作高度。 | H30: 生長點高度一致 | I30: 紀錄_田間作業 | J30: S14 | L30: 未開始 | N30: =IF(L30="完成","",IF(D30<TODAY(),"⚠ 已過預定日",IF(D30-TODAY()<=7,"本週到期","")))
A31: D04 | B31: 結果採收 | C31: =參數與用量計算!$B$18 -> 11 | D31: =參數與用量計算!$B$4+C31*7 -> 46387 | E31: 每週1–3次 | F31: 採收 | G31: 果實紅熟且硬度高時採收,糖度應達7°Brix以上;夏季提早採收避免裂果。每天記錄採收日期、區塊、作業人員。 | H31: 每批抽測糖度≥7 | I31: 紀錄_採收出貨 | J31: S1、S12、S2 | L31: 未開始 | N31: =IF(L31="完成","",IF(D31<TODAY(),"⚠ 已過預定日",IF(D31-TODAY()<=7,"本週到期","")))
A32: D05 | B32: 結果採收 | C32: =參數與用量計算!$B$18 -> 11 | D32: =參數與用量計算!$B$4+C32*7 -> 46387 | E32: 每批 | F32: 採後處理與貯藏 | G32: 採後移至陰涼處分級、預冷、包裝;淡紅果10–12.5°C、紅熟硬果7–10°C可放3–5天,相對濕度90–95%;低於10°C超過2週會寒害;不與對乙烯敏感的蔬菜同庫。冷藏溫度每天記錄。 | H32: 冷藏溫度紀錄完整 | I32: 紀錄_採收出貨 | J32: S20、S2 | L32: 未開始 | N32: =IF(L32="完成","",IF(D32<TODAY(),"⚠ 已過預定日",IF(D32-TODAY()<=7,"本週到期","")))
A33: D06 | B33: 結果採收 | C33: =參數與用量計算!$B$18 -> 11 | D33: =參數與用量計算!$B$4+C33*7 -> 46387 | E33: 每期作1次 | F33: 農藥殘留檢驗 | G33: 首批採收前後送驗果實農藥殘留,每期作至少一次,報告存檔。 | H33: 檢驗合格報告 | I33: 紀錄_病蟲害防治 | J33: S2 | L33: 未開始 | N33: =IF(L33="完成","",IF(D33<TODAY(),"⚠ 已過預定日",IF(D33-TODAY()<=7,"本週到期","")))
A34: D07 | B34: 結果採收 | C34: =參數與用量計算!$B$18 -> 11 | D34: =參數與用量計算!$B$4+C34*7 -> 46387 | E34: 每期作1次(選用) | F34: 葉片營養分析 | G34: 採15–20片生長點往下第3–4片的完整成熟葉送驗,確認氮磷鉀鈣鎂是否不足。 | H34: 取得分析報告 | I34: 紀錄_施肥灌溉 | J34: S13 | L34: 未開始 | N34: =IF(L34="完成","",IF(D34<TODAY(),"⚠ 已過預定日",IF(D34-TODAY()<=7,"本週到期","")))
A35: D08 | B35: 結果採收 | C35: =參數與用量計算!$B$18 -> 11 | D35: =參數與用量計算!$B$4+C35*7 -> 46387 | E35: 高溫期 | F35: 高溫期補鈣與降溫 | G35: 日溫高於26°C、夜溫高於20°C即進入高溫障礙;30°C以上花粉管發育受阻。高溫期每7–10天葉面噴水溶鈣1次,連續2–3次;開遮陰網、提高供水頻率降低根溫。 | H35: 高溫期落花、尻腐比例下降 | I35: 紀錄_施肥灌溉 | J35: S4 | L35: 未開始 | N35: =IF(L35="完成","",IF(D35<TODAY(),"⚠ 已過預定日",IF(D35-TODAY()<=7,"本週到期","")))
A36: E01 | B36: 作期末 | C36: =參數與用量計算!$B$19-6 -> 24 | D36: =參數與用量計算!$B$4+C36*7 -> 46478 | E36: 一次 | F36: 摘心 | G36: 作期結束前6週摘除頂芽,讓養分集中到已著果的果房。之後停止授粉與生長量測。 | H36: 全部幹摘心 | I36: 紀錄_田間作業 | J36: S12 | L36: 未開始 | N36: =IF(L36="完成","",IF(D36<TODAY(),"⚠ 已過預定日",IF(D36-TODAY()<=7,"本週到期","")))
A37: E02 | B37: 作期末 | C37: =參數與用量計算!$B$19+1 -> 31 | D37: =參數與用量計算!$B$4+C37*7 -> 46527 | E37: 一次 | F37: 清園 | G37: 末採後拔除植株、殘根、落果並帶離溫室;回收滴帶、吊繩、黏紙;蜂箱撤出。 | H37: 溫室內無植株殘體 | I37: 紀錄_田間作業 | J37: S8 | L37: 未開始 | N37: =IF(L37="完成","",IF(D37<TODAY(),"⚠ 已過預定日",IF(D37-TODAY()<=7,"本週到期","")))
A38: E03 | B38: 作期末 | C38: =參數與用量計算!$B$19+1 -> 31 | D38: =參數與用量計算!$B$4+C38*7 -> 46527 | E38: 一次 | F38: 作後土壤檢測與休閒規劃 | G38: 採土驗pH、EC;EC偏高則安排淋洗、有機質改良(見A03);有青枯病、線蟲發生則規劃輪作或嫁接苗。 | H38: 下期作土壤改良計畫 | I38: 紀錄_施肥灌溉 | J38: S2、S10、S6 | L38: 未開始 | N38: =IF(L38="完成","",IF(D38<TODAY(),"⚠ 已過預定日",IF(D38-TODAY()<=7,"本週到期","")))
A39: E04 | B39: 作期末 | C39: =參數與用量計算!$B$19+1 -> 31 | D39: =參數與用量計算!$B$4+C39*7 -> 46527 | E39: 一次 | F39: 作期檢討 | G39: 彙整總產量(kg/分地)、特級果比例、糖度、用肥量、病蟲害發生與防治成效、工時。參考:臺中場秋作玉女(籃耕介質、雙幹)總產量2,019 kg/0.1公頃、特級果91.9%。 | H39: 完成檢討報告 | I39: 紀錄_採收出貨 | J39: S5 | L39: 未開始 | N39: =IF(L39="完成","",IF(D39<TODAY(),"⚠ 已過預定日",IF(D39-TODAY()<=7,"本週到期","")))

Sheet 週曆排程
A1: 週曆排程(●=本週執行 ★=關鍵節點)
A2: 週次與日期隨「參數與用量計算」自動更新
A3: 週次 | B3: 週起日 | C3: 週迄日 | D3: 生育階段 | E3: 訂苗/驗苗 | F3: 整地基肥 | G3: 定植 | H3: 誘引/摘側芽 | I3: 授粉 | J3: 追肥 | K3: 生長量測 | L3: 黏紙監測 | M3: 摘下位葉 | N3: 採收 | O3: 摘心 | P3: 清園/驗土 | Q3: 本週清單項目數 | R3: 本週備註
A4: -8 | B4: =參數與用量計算!$B$4+$A4*7 -> 46254 | C4: =B4+6 -> 46260 | D4: =IF($A4<0,"作前準備",IF($A4<=1,"定植緩苗",IF($A4<參數與用量計算!$B$14,"營養生長",IF($A4<參數與用量計算!$B$18,"開花著果",IF($A4<=參數與用量計算!$B$19,"採收期",IF($A4=參數與用量計算!$B$19+1,"清園","作後休閒")))))) -> 作前準備 | E4: =IF(OR($A4=-MAX(參數與用量計算!$B$13,2),$A4=0),"★","") | F4: =IF(OR($A4=-3,$A4=-2),"●","") | G4: =IF($A4=0,"★","") | H4: =IF(AND($A4>=1,$A4<=參數與用量計算!$B$19-6),"●","") | I4: =IF(AND($A4>=參數與用量計算!$B$14,$A4<=參數與用量計算!$B$19-6),"●","") | J4: =IF(AND($A4>=參數與用量計算!$B$15,MOD($A4-參數與用量計算!$B$15,參數與用量計算!$B$16)=0,($A4-參數與用量計算!$B$15)/參數與用量計算!$B$16<參數與用量計算!$B$17),"●","") | K4: =IF(AND($A4>=參數與用量計算!$B$14,$A4<=參數與用量計算!$B$19-6),"●","") | L4: =IF(AND($A4>=-1,$A4<=參數與用量計算!$B$19),"●","") | M4: =IF(AND($A4>=參數與用量計算!$B$18,$A4<=參數與用量計算!$B$19),"●","") | N4: =IF(AND($A4>=參數與用量計算!$B$18,$A4<=參數與用量計算!$B$19),"●","") | O4: =IF($A4=參數與用量計算!$B$19-6,"★","") | P4: =IF(OR($A4=參數與用量計算!$B$19+1,$A4=-8),"★","") -> ★ | Q4: =COUNTIF(階段工作清單!$C$4:$C$39,$A4) -> 3
A5: -7 | B5: =參數與用量計算!$B$4+$A5*7 -> 46261 | C5: =B5+6 -> 46267 | D5: =IF($A5<0,"作前準備",IF($A5<=1,"定植緩苗",IF($A5<參數與用量計算!$B$14,"營養生長",IF($A5<參數與用量計算!$B$18,"開花著果",IF($A5<=參數與用量計算!$B$19,"採收期",IF($A5=參數與用量計算!$B$19+1,"清園","作後休閒")))))) -> 作前準備 | E5: =IF(OR($A5=-MAX(參數與用量計算!$B$13,2),$A5=0),"★","") | F5: =IF(OR($A5=-3,$A5=-2),"●","") | G5: =IF($A5=0,"★","") | H5: =IF(AND($A5>=1,$A5<=參數與用量計算!$B$19-6),"●","") | I5: =IF(AND($A5>=參數與用量計算!$B$14,$A5<=參數與用量計算!$B$19-6),"●","") | J5: =IF(AND($A5>=參數與用量計算!$B$15,MOD($A5-參數與用量計算!$B$15,參數與用量計算!$B$16)=0,($A5-參數與用量計算!$B$15)/參數與用量計算!$B$16<參數與用量計算!$B$17),"●","") | K5: =IF(AND($A5>=參數與用量計算!$B$14,$A5<=參數與用量計算!$B$19-6),"●","") | L5: =IF(AND($A5>=-1,$A5<=參數與用量計算!$B$19),"●","") | M5: =IF(AND($A5>=參數與用量計算!$B$18,$A5<=參數與用量計算!$B$19),"●","") | N5: =IF(AND($A5>=參數與用量計算!$B$18,$A5<=參數與用量計算!$B$19),"●","") | O5: =IF($A5=參數與用量計算!$B$19-6,"★","") | P5: =IF(OR($A5=參數與用量計算!$B$19+1,$A5=-8),"★","") | Q5: =COUNTIF(階段工作清單!$C$4:$C$39,$A5) -> 1
A6: -6 | B6: =參數與用量計算!$B$4+$A6*7 -> 46268 | C6: =B6+6 -> 46274 | D6: =IF($A6<0,"作前準備",IF($A6<=1,"定植緩苗",IF($A6<參數與用量計算!$B$14,"營養生長",IF($A6<參數與用量計算!$B$18,"開花著果",IF($A6<=參數與用量計算!$B$19,"採收期",IF($A6=參數與用量計算!$B$19+1,"清園","作後休閒")))))) -> 作前準備 | E6: =IF(OR($A6=-MAX(參數與用量計算!$B$13,2),$A6=0),"★","") | F6: =IF(OR($A6=-3,$A6=-2),"●","") | G6: =IF($A6=0,"★","") | H6: =IF(AND($A6>=1,$A6<=參數與用量計算!$B$19-6),"●","") | I6: =IF(AND($A6>=參數與用量計算!$B$14,$A6<=參數與用量計算!$B$19-6),"●","") | J6: =IF(AND($A6>=參數與用量計算!$B$15,MOD($A6-參數與用量計算!$B$15,參數與用量計算!$B$16)=0,($A6-參數與用量計算!$B$15)/參數與用量計算!$B$16<參數與用量計算!$B$17),"●","") | K6: =IF(AND($A6>=參數與用量計算!$B$14,$A6<=參數與用量計算!$B$19-6),"●","") | L6: =IF(AND($A6>=-1,$A6<=參數與用量計算!$B$19),"●","") | M6: =IF(AND($A6>=參數與用量計算!$B$18,$A6<=參數與用量計算!$B$19),"●","") | N6: =IF(AND($A6>=參數與用量計算!$B$18,$A6<=參數與用量計算!$B$19),"●","") | O6: =IF($A6=參數與用量計算!$B$19-6,"★","") | P6: =IF(OR($A6=參數與用量計算!$B$19+1,$A6=-8),"★","") | Q6: =COUNTIF(階段工作清單!$C$4:$C$39,$A6) -> 1
A7: -5 | B7: =參數與用量計算!$B$4+$A7*7 -> 46275 | C7: =B7+6 -> 46281 | D7: =IF($A7<0,"作前準備",IF($A7<=1,"定植緩苗",IF($A7<參數與用量計算!$B$14,"營養生長",IF($A7<參數與用量計算!$B$18,"開花著果",IF($A7<=參數與用量計算!$B$19,"採收期",IF($A7=參數與用量計算!$B$19+1,"清園","作後休閒")))))) -> 作前準備 | E7: =IF(OR($A7=-MAX(參數與用量計算!$B$13,2),$A7=0),"★","") | F7: =IF(OR($A7=-3,$A7=-2),"●","") | G7: =IF($A7=0,"★","") | H7: =IF(AND($A7>=1,$A7<=參數與用量計算!$B$19-6),"●","") | I7: =IF(AND($A7>=參數與用量計算!$B$14,$A7<=參數與用量計算!$B$19-6),"●","") | J7: =IF(AND($A7>=參數與用量計算!$B$15,MOD($A7-參數與用量計算!$B$15,參數與用量計算!$B$16)=0,($A7-參數與用量計算!$B$15)/參數與用量計算!$B$16<參數與用量計算!$B$17),"●","") | K7: =IF(AND($A7>=參數與用量計算!$B$14,$A7<=參數與用量計算!$B$19-6),"●","") | L7: =IF(AND($A7>=-1,$A7<=參數與用量計算!$B$19),"●","") | M7: =IF(AND($A7>=參數與用量計算!$B$18,$A7<=參數與用量計算!$B$19),"●","") | N7: =IF(AND($A7>=參數與用量計算!$B$18,$A7<=參數與用量計算!$B$19),"●","") | O7: =IF($A7=參數與用量計算!$B$19-6,"★","") | P7: =IF(OR($A7=參數與用量計算!$B$19+1,$A7=-8),"★","") | Q7: =COUNTIF(階段工作清單!$C$4:$C$39,$A7) -> 0
A8: -4 | B8: =參數與用量計算!$B$4+$A8*7 -> 46282 | C8: =B8+6 -> 46288 | D8: =IF($A8<0,"作前準備",IF($A8<=1,"定植緩苗",IF($A8<參數與用量計算!$B$14,"營養生長",IF($A8<參數與用量計算!$B$18,"開花著果",IF($A8<=參數與用量計算!$B$19,"採收期",IF($A8=參數與用量計算!$B$19+1,"清園","作後休閒")))))) -> 作前準備 | E8: =IF(OR($A8=-MAX(參數與用量計算!$B$13,2),$A8=0),"★","") | F8: =IF(OR($A8=-3,$A8=-2),"●","") | G8: =IF($A8=0,"★","") | H8: =IF(AND($A8>=1,$A8<=參數與用量計算!$B$19-6),"●","") | I8: =IF(AND($A8>=參數與用量計算!$B$14,$A8<=參數與用量計算!$B$19-6),"●","") | J8: =IF(AND($A8>=參數與用量計算!$B$15,MOD($A8-參數與用量計算!$B$15,參數與用量計算!$B$16)=0,($A8-參數與用量計算!$B$15)/參數與用量計算!$B$16<參數與用量計算!$B$17),"●","") | K8: =IF(AND($A8>=參數與用量計算!$B$14,$A8<=參數與用量計算!$B$19-6),"●","") | L8: =IF(AND($A8>=-1,$A8<=參數與用量計算!$B$19),"●","") | M8: =IF(AND($A8>=參數與用量計算!$B$18,$A8<=參數與用量計算!$B$19),"●","") | N8: =IF(AND($A8>=參數與用量計算!$B$18,$A8<=參數與用量計算!$B$19),"●","") | O8: =IF($A8=參數與用量計算!$B$19-6,"★","") | P8: =IF(OR($A8=參數與用量計算!$B$19+1,$A8=-8),"★","") | Q8: =COUNTIF(階段工作清單!$C$4:$C$39,$A8) -> 0
A9: -3 | B9: =參數與用量計算!$B$4+$A9*7 -> 46289 | C9: =B9+6 -> 46295 | D9: =IF($A9<0,"作前準備",IF($A9<=1,"定植緩苗",IF($A9<參數與用量計算!$B$14,"營養生長",IF($A9<參數與用量計算!$B$18,"開花著果",IF($A9<=參數與用量計算!$B$19,"採收期",IF($A9=參數與用量計算!$B$19+1,"清園","作後休閒")))))) -> 作前準備 | E9: =IF(OR($A9=-MAX(參數與用量計算!$B$13,2),$A9=0),"★","") | F9: =IF(OR($A9=-3,$A9=-2),"●","") -> ● | G9: =IF($A9=0,"★","") | H9: =IF(AND($A9>=1,$A9<=參數與用量計算!$B$19-6),"●","") | I9: =IF(AND($A9>=參數與用量計算!$B$14,$A9<=參數與用量計算!$B$19-6),"●","") | J9: =IF(AND($A9>=參數與用量計算!$B$15,MOD($A9-參數與用量計算!$B$15,參數與用量計算!$B$16)=0,($A9-參數與用量計算!$B$15)/參數與用量計算!$B$16<參數與用量計算!$B$17),"●","") | K9: =IF(AND($A9>=參數與用量計算!$B$14,$A9<=參數與用量計算!$B$19-6),"●","") | L9: =IF(AND($A9>=-1,$A9<=參數與用量計算!$B$19),"●","") | M9: =IF(AND($A9>=參數與用量計算!$B$18,$A9<=參數與用量計算!$B$19),"●","") | N9: =IF(AND($A9>=參數與用量計算!$B$18,$A9<=參數與用量計算!$B$19),"●","") | O9: =IF($A9=參數與用量計算!$B$19-6,"★","") | P9: =IF(OR($A9=參數與用量計算!$B$19+1,$A9=-8),"★","") | Q9: =COUNTIF(階段工作清單!$C$4:$C$39,$A9) -> 1
A10: -2 | B10: =參數與用量計算!$B$4+$A10*7 -> 46296 | C10: =B10+6 -> 46302 | D10: =IF($A10<0,"作前準備",IF($A10<=1,"定植緩苗",IF($A10<參數與用量計算!$B$14,"營養生長",IF($A10<參數與用量計算!$B$18,"開花著果",IF($A10<=參數與用量計算!$B$19,"採收期",IF($A10=參數與用量計算!$B$19+1,"清園","作後休閒")))))) -> 作前準備 | E10: =IF(OR($A10=-MAX(參數與用量計算!$B$13,2),$A10=0),"★","") -> ★ | F10: =IF(OR($A10=-3,$A10=-2),"●","") -> ● | G10: =IF($A10=0,"★","") | H10: =IF(AND($A10>=1,$A10<=參數與用量計算!$B$19-6),"●","") | I10: =IF(AND($A10>=參數與用量計算!$B$14,$A10<=參數與用量計算!$B$19-6),"●","") | J10: =IF(AND($A10>=參數與用量計算!$B$15,MOD($A10-參數與用量計算!$B$15,參數與用量計算!$B$16)=0,($A10-參數與用量計算!$B$15)/參數與用量計算!$B$16<參數與用量計算!$B$17),"●","") | K10: =IF(AND($A10>=參數與用量計算!$B$14,$A10<=參數與用量計算!$B$19-6),"●","") | L10: =IF(AND($A10>=-1,$A10<=參數與用量計算!$B$19),"●","") | M10: =IF(AND($A10>=參數與用量計算!$B$18,$A10<=參數與用量計算!$B$19),"●","") | N10: =IF(AND($A10>=參數與用量計算!$B$18,$A10<=參數與用量計算!$B$19),"●","") | O10: =IF($A10=參數與用量計算!$B$19-6,"★","") | P10: =IF(OR($A10=參數與用量計算!$B$19+1,$A10=-8),"★","") | Q10: =COUNTIF(階段工作清單!$C$4:$C$39,$A10) -> 2
A11: -1 | B11: =參數與用量計算!$B$4+$A11*7 -> 46303 | C11: =B11+6 -> 46309 | D11: =IF($A11<0,"作前準備",IF($A11<=1,"定植緩苗",IF($A11<參數與用量計算!$B$14,"營養生長",IF($A11<參數與用量計算!$B$18,"開花著果",IF($A11<=參數與用量計算!$B$19,"採收期",IF($A11=參數與用量計算!$B$19+1,"清園","作後休閒")))))) -> 作前準備 | E11: =IF(OR($A11=-MAX(參數與用量計算!$B$13,2),$A11=0),"★","") | F11: =IF(OR($A11=-3,$A11=-2),"●","") | G11: =IF($A11=0,"★","") | H11: =IF(AND($A11>=1,$A11<=參數與用量計算!$B$19-6),"●","") | I11: =IF(AND($A11>=參數與用量計算!$B$14,$A11<=參數與用量計算!$B$19-6),"●","") | J11: =IF(AND($A11>=參數與用量計算!$B$15,MOD($A11-參數與用量計算!$B$15,參數與用量計算!$B$16)=0,($A11-參數與用量計算!$B$15)/參數與用量計算!$B$16<參數與用量計算!$B$17),"●","") | K11: =IF(AND($A11>=參數與用量計算!$B$14,$A11<=參數與用量計算!$B$19-6),"●","") | L11: =IF(AND($A11>=-1,$A11<=參數與用量計算!$B$19),"●","") -> ● | M11: =IF(AND($A11>=參數與用量計算!$B$18,$A11<=參數與用量計算!$B$19),"●","") | N11: =IF(AND($A11>=參數與用量計算!$B$18,$A11<=參數與用量計算!$B$19),"●","") | O11: =IF($A11=參數與用量計算!$B$19-6,"★","") | P11: =IF(OR($A11=參數與用量計算!$B$19+1,$A11=-8),"★","") | Q11: =COUNTIF(階段工作清單!$C$4:$C$39,$A11) -> 2
A12: 0 | B12: =參數與用量計算!$B$4+$A12*7 -> 46310 | C12: =B12+6 -> 46316 | D12: =IF($A12<0,"作前準備",IF($A12<=1,"定植緩苗",IF($A12<參數與用量計算!$B$14,"營養生長",IF($A12<參數與用量計算!$B$18,"開花著果",IF($A12<=參數與用量計算!$B$19,"採收期",IF($A12=參數與用量計算!$B$19+1,"清園","作後休閒")))))) -> 定植緩苗 | E12: =IF(OR($A12=-MAX(參數與用量計算!$B$13,2),$A12=0),"★","") -> ★ | F12: =IF(OR($A12=-3,$A12=-2),"●","") | G12: =IF($A12=0,"★","") -> ★ | H12: =IF(AND($A12>=1,$A12<=參數與用量計算!$B$19-6),"●","") | I12: =IF(AND($A12>=參數與用量計算!$B$14,$A12<=參數與用量計算!$B$19-6),"●","") | J12: =IF(AND($A12>=參數與用量計算!$B$15,MOD($A12-參數與用量計算!$B$15,參數與用量計算!$B$16)=0,($A12-參數與用量計算!$B$15)/參數與用量計算!$B$16<參數與用量計算!$B$17),"●","") | K12: =IF(AND($A12>=參數與用量計算!$B$14,$A12<=參數與用量計算!$B$19-6),"●","") | L12: =IF(AND($A12>=-1,$A12<=參數與用量計算!$B$19),"●","") -> ● | M12: =IF(AND($A12>=參數與用量計算!$B$18,$A12<=參數與用量計算!$B$19),"●","") | N12: =IF(AND($A12>=參數與用量計算!$B$18,$A12<=參數與用量計算!$B$19),"●","") | O12: =IF($A12=參數與用量計算!$B$19-6,"★","") | P12: =IF(OR($A12=參數與用量計算!$B$19+1,$A12=-8),"★","") | Q12: =COUNTIF(階段工作清單!$C$4:$C$39,$A12) -> 3
A13: 1 | B13: =參數與用量計算!$B$4+$A13*7 -> 46317 | C13: =B13+6 -> 46323 | D13: =IF($A13<0,"作前準備",IF($A13<=1,"定植緩苗",IF($A13<參數與用量計算!$B$14,"營養生長",IF($A13<參數與用量計算!$B$18,"開花著果",IF($A13<=參數與用量計算!$B$19,"採收期",IF($A13=參數與用量計算!$B$19+1,"清園","作後休閒")))))) -> 定植緩苗 | E13: =IF(OR($A13=-MAX(參數與用量計算!$B$13,2),$A13=0),"★","") | F13: =IF(OR($A13=-3,$A13=-2),"●","") | G13: =IF($A13=0,"★","") | H13: =IF(AND($A13>=1,$A13<=參數與用量計算!$B$19-6),"●","") -> ● | I13: =IF(AND($A13>=參數與用量計算!$B$14,$A13<=參數與用量計算!$B$19-6),"●","") | J13: =IF(AND($A13>=參數與用量計算!$B$15,MOD($A13-參數與用量計算!$B$15,參數與用量計算!$B$16)=0,($A13-參數與用量計算!$B$15)/參數與用量計算!$B$16<參數與用量計算!$B$17),"●","") | K13: =IF(AND($A13>=參數與用量計算!$B$14,$A13<=參數與用量計算!$B$19-6),"●","") | L13: =IF(AND($A13>=-1,$A13<=參數與用量計算!$B$19),"●","") -> ● | M13: =IF(AND($A13>=參數與用量計算!$B$18,$A13<=參數與用量計算!$B$19),"●","") | N13: =IF(AND($A13>=參數與用量計算!$B$18,$A13<=參數與用量計算!$B$19),"●","") | O13: =IF($A13=參數與用量計算!$B$19-6,"★","") | P13: =IF(OR($A13=參數與用量計算!$B$19+1,$A13=-8),"★","") | Q13: =COUNTIF(階段工作清單!$C$4:$C$39,$A13) -> 2
A14: 2 | B14: =參數與用量計算!$B$4+$A14*7 -> 46324 | C14: =B14+6 -> 46330 | D14: =IF($A14<0,"作前準備",IF($A14<=1,"定植緩苗",IF($A14<參數與用量計算!$B$14,"營養生長",IF($A14<參數與用量計算!$B$18,"開花著果",IF($A14<=參數與用量計算!$B$19,"採收期",IF($A14=參數與用量計算!$B$19+1,"清園","作後休閒")))))) -> 營養生長 | E14: =IF(OR($A14=-MAX(參數與用量計算!$B$13,2),$A14=0),"★","") | F14: =IF(OR($A14=-3,$A14=-2),"●","") | G14: =IF($A14=0,"★","") | H14: =IF(AND($A14>=1,$A14<=參數與用量計算!$B$19-6),"●","") -> ● | I14: =IF(AND($A14>=參數與用量計算!$B$14,$A14<=參數與用量計算!$B$19-6),"●","") | J14: =IF(AND($A14>=參數與用量計算!$B$15,MOD($A14-參數與用量計算!$B$15,參數與用量計算!$B$16)=0,($A14-參數與用量計算!$B$15)/參數與用量計算!$B$16<參數與用量計算!$B$17),"●","") | K14: =IF(AND($A14>=參數與用量計算!$B$14,$A14<=參數與用量計算!$B$19-6),"●","") | L14: =IF(AND($A14>=-1,$A14<=參數與用量計算!$B$19),"●","") -> ● | M14: =IF(AND($A14>=參數與用量計算!$B$18,$A14<=參數與用量計算!$B$19),"●","") | N14: =IF(AND($A14>=參數與用量計算!$B$18,$A14<=參數與用量計算!$B$19),"●","") | O14: =IF($A14=參數與用量計算!$B$19-6,"★","") | P14: =IF(OR($A14=參數與用量計算!$B$19+1,$A14=-8),"★","") | Q14: =COUNTIF(階段工作清單!$C$4:$C$39,$A14) -> 2
A15: 3 | B15: =參數與用量計算!$B$4+$A15*7 -> 46331 | C15: =B15+6 -> 46337 | D15: =IF($A15<0,"作前準備",IF($A15<=1,"定植緩苗",IF($A15<參數與用量計算!$B$14,"營養生長",IF($A15<參數與用量計算!$B$18,"開花著果",IF($A15<=參數與用量計算!$B$19,"採收期",IF($A15=參數與用量計算!$B$19+1,"清園","作後休閒")))))) -> 開花著果 | E15: =IF(OR($A15=-MAX(參數與用量計算!$B$13,2),$A15=0),"★","") | F15: =IF(OR($A15=-3,$A15=-2),"●","") | G15: =IF($A15=0,"★","") | H15: =IF(AND($A15>=1,$A15<=參數與用量計算!$B$19-6),"●","") -> ● | I15: =IF(AND($A15>=參數與用量計算!$B$14,$A15<=參數與用量計算!$B$19-6),"●","") -> ● | J15: =IF(AND($A15>=參數與用量計算!$B$15,MOD($A15-參數與用量計算!$B$15,參數與用量計算!$B$16)=0,($A15-參數與用量計算!$B$15)/參數與用量計算!$B$16<參數與用量計算!$B$17),"●","") | K15: =IF(AND($A15>=參數與用量計算!$B$14,$A15<=參數與用量計算!$B$19-6),"●","") -> ● | L15: =IF(AND($A15>=-1,$A15<=參數與用量計算!$B$19),"●","") -> ● | M15: =IF(AND($A15>=參數與用量計算!$B$18,$A15<=參數與用量計算!$B$19),"●","") | N15: =IF(AND($A15>=參數與用量計算!$B$18,$A15<=參數與用量計算!$B$19),"●","") | O15: =IF($A15=參數與用量計算!$B$19-6,"★","") | P15: =IF(OR($A15=參數與用量計算!$B$19+1,$A15=-8),"★","") | Q15: =COUNTIF(階段工作清單!$C$4:$C$39,$A15) -> 5
... A44: 32 | B44: =參數與用量計算!$B$4+$A44*7 -> 46534 | C44: =B44+6 -> 46540 | D44: =IF($A44<0,"作前準備",IF($A44<=1,"定植緩苗",IF($A44<參數與用量計算!$B$14,"營養生長",IF($A44<參數與用量計算!$B$18,"開花著果",IF($A44<=參數與用量計算!$B$19,"採收期",IF($A44=參數與用量計算!$B$19+1,"清園","作後休閒")))))) -> 作後休閒 | E44: =IF(OR($A44=-MAX(參數與用量計算!$B$13,2),$A44=0),"★","") | F44: =IF(OR($A44=-3,$A44=-2),"●","") | G44: =IF($A44=0,"★","") | H44: =IF(AND($A44>=1,$A44<=參數與用量計算!$B$19-6),"●","") | I44: =IF(AND($A44>=參數與用量計算!$B$14,$A44<=參數與用量計算!$B$19-6),"●","") | J44: =IF(AND($A44>=參數與用量計算!$B$15,MOD($A44-參數與用量計算!$B$15,參數與用量計算!$B$16)=0,($A44-參數與用量計算!$B$15)/參數與用量計算!$B$16<參數與用量計算!$B$17),"●","") | K44: =IF(AND($A44>=參數與用量計算!$B$14,$A44<=參數與用量計算!$B$19-6),"●","") | L44: =IF(AND($A44>=-1,$A44<=參數與用量計算!$B$19),"●","") | M44: =IF(AND($A44>=參數與用量計算!$B$18,$A44<=參數與用量計算!$B$19),"●","") | N44: =IF(AND($A44>=參數與用量計算!$B$18,$A44<=參數與用量計算!$B$19),"●","") | O44: =IF($A44=參數與用量計算!$B$19-6,"★","") | P44: =IF(OR($A44=參數與用量計算!$B$19+1,$A44=-8),"★","") | Q44: =COUNTIF(階段工作清單!$C$4:$C$39,$A44) -> 0
A46: 註:「本週清單項目數」為「階段工作清單」中起始週次落在該週的工作數,可到清單以「起始週次」篩選查看。首採週為估計值。

Sheet 例行作業檢查表
A1: 例行作業檢查表(每週列印一張)
A2: 週次:______ 日期:____/____ ~ ____/____ 管理者簽核:__________
A3: 頻率 | B3: 作業項目 | C3: 執行標準 | D3: 來源 | E3: 負責人 | F3: 一 | G3: 二 | H3: 三 | I3: 四 | J3: 五 | K3: 六 | L3: 日 | M3: 異常說明
A4: 每日 | B4: 溫濕度巡查紀錄 | C4: 記錄最高/最低溫與RH。生產期目標:白天21–27°C、夜間17–18°C;RH 50–70%,不超過90%。國內:日溫>26°C且夜溫>20°C為高溫障礙;開花期<15°C花粉發育不良、>35°C妨礙雌雄蕊發育。 | D4: S17、S16、S13、S4、S9
A5: 每日 | B5: 通風/遮陰/風扇操作 | C5: 日出後通風排濕並開循環風扇;晴天夜溫17–18°C、陰天後16–17°C;高溫期開遮陰網。 | D5: S13、S4
A6: 每日 | B6: 滴灌系統巡查 | C6: 檢查滴帶破損、堵塞、漏水;畦面濕潤是否均勻;避免忽乾忽濕(裂果、尻腐)。 | D6: S13
A7: 每日 | B7: 病株/病葉/病果清除 | C7: 發現捲葉病毒株、青枯株、灰黴病果,裝袋帶離園區;青枯株切莖泡水見乳白菌泥即確認。 | D7: S8、S6
A8: 每日(出貨期) | B8: 採收與冷藏溫度紀錄 | C8: 記錄採收日期、區塊、作業人員;冷藏庫溫度每天記錄。 | D8: S2
A9: 每2天 | B9: 熊蜂咬痕檢查 | C9: 不同位置採20朵已閉合花,應全部有咬痕;咬痕僅剩1–2個/朵時補新箱。 | D9: S18
A10: 每週 | B10: 摘側芽 | C10: 側芽5–7.5 cm前摘除,晴天乾燥時段進行。 | D10: S12、S13
A11: 每週 | B11: 誘引夾莖 | C11: 每約25 cm夾一次,夾在兩葉之間、不夾花序下。 | D11: S12、S14
A12: 每週 | B12: 摘下位葉 | C12: 採收完果房以下葉片全摘+再摘上方1片;維持1.5–1.8 m葉幕。 | D12: S14、S12
A13: 每週 | B13: 疏果(依品種) | C13: 小果每穗留8–10果。 | D13: S12
A14: 每週 | B14: 黏紙計數與更換 | C14: 每張黏紙計數粉蝨、薊馬、斑潛蠅,記錄隻數;蟲量少可續用。 | D14: S19
A15: 每週 | B15: 生長量測10株 | C15: 莖徑、花距、新開花序數、著果數。 | D15: S15
... A23: 每年/每2年 | B23: 人員健康檢查/安全用藥講習 | C23: 健康檢查每年1次;安全用藥講習2年1次。 | D23: S2

Sheet 管理數值標準
A1: 管理數值標準
A2: 國內=臺灣改良場/農業部資料;國外=美國推廣單位、荷蘭資材商、國際文獻(多為介質栽培,請當參考)
A3: 類別 | B3: 項目 | C3: 數值 / 做法 | D3: 適用時期 | E3: 國內/國外 | F3: 來源
A4: 溫度 | B4: 最適生長溫度 | C4: 20–25°C | D4: 全期 | E4: 國內 | F4: S4
A5: 溫度 | B5: 高溫障礙 | C5: 日溫高於26°C、夜溫超過20°C;設施內白天常超過35°C;30°C以上花粉管發育受阻 | D5: 高溫期 | E5: 國內 | F5: S4
A6: 溫度 | B6: 開花適溫 | C6: 20–30°C;15°C花粉發育不良;10°C以下授精不良大量落花;35°C以上妨礙雌雄蕊發育 | D6: 開花期 | E6: 國內 | F6: S9
A7: 溫度 | B7: 生產期日/夜溫 | C7: 白天21–27°C、夜間17–18°C;成株白天20–22°C、夜間17–19°C;30°C以上茄紅素形成受阻(轉色不良) | D7: 結果期 | E7: 國外 | F7: S17
A8: 溫度 | B8: 夜溫依日照調整 | C8: 晴天後夜溫17–18°C(62–65°F);陰天後16–17°C(60–62°F);低於13°C或高於35°C會落花 | D8: 全期 | E8: 國外 | F8: S13
A9: 溫度 | B9: 定植後溫度 | C9: 定植後24°C維持1–2天,再逐日降溫至19°C(可控溫溫室) | D9: 定植 | E9: 國外 | F9: S17
A10: 濕度 | B10: 相對濕度 | C10: 最適50–70%;不超過85–90%以免葉部病害 | D10: 全期 | E10: 國外 | F10: S16、S13
A11: 濕度 | B11: 授粉濕度 | C11: RH約70%最佳;>80%花粉黏結、<60%柱頭乾燥;熊蜂授粉花粉釋放RH 50–80% | D11: 開花期 | E11: 國外 | F11: S17、S18
A12: 濕度 | B12: 飽差VPD | C12: 0.4–0.8 kPa | D12: 全期 | E12: 國外 | F12: S16
A13: 土壤 | B13: pH / EC | C13: pH 5.6–7.0;EC不超過2.0 dS/m | D13: 作前 | E13: 國內 | F13: S2
A14: 土壤 | B14: 鹽化改良 | C14: 低養分纖維質堆肥10–20公噸/公頃,或稻草約1公噸/分地(1個月以上分解);暗渠排水埋深60–80 cm | D14: 休閒期 | E14: 國內 | F14: S10
... A40: 產量 | B40: 參考產量 | C40: 臺中場秋作玉女(籃耕泥炭介質、雙幹直立):總產量2,019 kg/0.1公頃,特級果91.9% | D40: 參考 | E40: 國內 | F40: S5

Sheet 病蟲害監測防治
A1: 病蟲害監測與防治作業
A2: 用藥一律先查「農藥資訊服務網」番茄現行登記(S22),遵守安全採收期並記錄
A3: 病蟲害 | B3: 高風險時期/條件 | C3: 監測方法與頻率 | D3: 判斷/行動門檻 | E3: 非化學防治作業 | F3: 用藥原則 | G3: 來源
A4: 銀葉粉蝨+番茄黃化捲葉病毒 | B4: 定植初期(秋作初期仍高溫) | C4: 黃色黏紙每週計數;每週翻看上位葉背 | D4: 病毒媒介害蟲宜低容忍:黏紙初見粉蝨即啟動防治;見捲葉株立即拔除 | E4: 要求育苗場以60目網隔離育苗、驗苗剔除捲葉苗;防蟲網修補、出入口隨手關門;病株裝袋帶出;國外以寄生蜂(Encarsia/Eretmocerus)於黏紙初見粉蝨時釋放,持續到寄生率80%(國內供應需洽詢) | F4: 查登記藥劑、輪替不同作用機制;放蜂期間先確認對熊蜂影響 | G4: S1、S8、S21、S18
A5: 薊馬 | B5: 乾燥、高溫期 | C5: 藍色黏紙監測,每週計數 | D5: 國外溫室一般參考:每張黏紙每週15隻;若已有番茄斑點萎凋病毒(Tospovirus)則1隻即行動(花卉作物數據,供參考) | E5: 清除雜草;藍色黏紙誘殺 | F5: 查登記藥劑 | G5: S8、S19
A6: 夜蛾類(番茄夜蛾、斜紋夜蛾) | B6: 結果期 | C6: 性費洛蒙誘蟲器每週計數;巡查蛀果 | D6: 誘蟲器捕獲量上升或見蛀孔果 | E6: 性費洛蒙誘殺;蛀果摘除帶出 | F6: 臺南場手冊列蘇力菌類;使用前查登記 | G6: S8、S1、S22
A7: 葉蟎 | B7: 高溫乾燥期 | C7: 每週翻看葉背,注意黃白斑點與細絲 | D7: 發現群聚即局部處理 | E7: 避免過度乾燥;清除嚴重受害葉 | F7: 窄域油類/查登記藥劑 | G7: S8
A8: 青枯病 | B8: 高溫多濕;低於20°C或土壤乾燥不利發病 | C8: 每日巡查萎凋株;切莖基部泡清水,見乳白色雲霧狀菌泥即確診 | D8: 確診即處理,並隔離該區灌溉水 | E8: 病株立即拔除帶出焚燬;減少給水次數與水量;築土堤隔離發病區;有病史田改用茄砧嫁接苗或與水稻輪作 | F8: 液化澱粉芽孢桿菌PMB01 200倍,每株莖基部澆0.2 L,發病初期起每7天1次,必要時連續5次 | G8: S6、S7
A9: 晚疫病 | B9: 冷涼多濕期 | C9: 每日巡查葉片水浸狀病斑 | D9: 發現病斑即清除並加強通風 | E9: 降低濕度、避免葉面長時間濕潤;病葉帶出 | F9: 預防:亞磷酸+氫氧化鉀1000倍;治療查登記藥劑 | G9: S8、S22
A10: 灰黴病/葉黴病 | B10: 高濕、盛花期、密植 | C10: 每日查花、果、下位葉 | D10: RH長時間>90%即為高風險 | E10: 日出後通風排濕、開循環風扇;摘除下位老葉;病花病果裝袋帶出 | F10: 查登記藥劑 | G10: S13、S14
A11: 白粉病 | B11: 乾濕交替期 | C11: 每週查葉面白色粉斑 | D11: 初見病斑即處理 | E11: 摘除病葉 | F11: 窄域油、葵無露等乳化油劑 | G11: S8
A12: 根瘤線蟲 | B12: 連作田、砂質土 | C12: 作前檢查前作根部是否有根瘤;生育期查萎凋株根部 | D12: 前作根瘤明顯即作前處理 | E12: 清除前作根系;輪作 | F12: TGAP:可於定植當日施用登記粒劑 | G12: S2
A13: 裂果/尻腐(生理障礙) | B13: 高溫期、灌水不均 | C13: 每次採收記錄裂果、尻腐比例 | D13: 比例上升即檢討灌水 | E13: 穩定灌水避免忽乾忽濕;高溫期葉面補鈣每7–10天1次連2–3次;夏季提早採收 | F13: — | G13: S13、S4、S1
A14: 落花落果(生理障礙) | B14: <15°C或>35°C | C14: 每週記錄著果數(生長量測) | D14: 著果數連續下降 | E14: 調整溫度;人工振動授粉或熊蜂;高溫期遮陰 | F14: 生長調節劑依S1倍數 | G14: S9、S1
A15: 用藥總則 | B15: 全期 | C15: — | D15: — | E15: 只使用合法登記藥劑;勿同時混用多種藥劑;作業人員2年1次安全用藥講習;每期作果實殘留檢驗1次 | F15: 每筆記錄資材名稱、倍數、日期、安全採收期 | G15: S2、S22

Sheet 紀錄_田間作業
A1: 田間作業紀錄
A2: 第4列灰底為填寫範例;依TGAP產銷履歷紀錄需求設計(S2)
A3: 日期 | B3: 棟別/區塊 | C3: 工作編號 | D3: 作業項目 | E3: 作業內容說明 | F3: 作業人員 | G3: 工時(小時) | H3: 備註
A4: 46324 | B4: A棟 | C4: C01 | D4: 摘側芽 | E4: 全棟摘除側芽,最長約6 cm | F4: 王小明 | G4: 3.5 | H4: 東側3株捲葉已拔除

Sheet 紀錄_施肥灌溉
A1: 施肥與灌溉紀錄
A2: 第4列灰底為填寫範例;依TGAP產銷履歷紀錄需求設計(S2)
A3: 日期 | B3: 棟別/區塊 | C3: 類別 | D3: 肥料名稱 | E3: 成分 N-P₂O₅-K₂O | F3: 用量(kg) | G3: 稀釋倍數/滴灌時間 | H3: 施用方式 | I3: 土壤EC(dS/m) | J3: 土壤pH | K3: 作業人員
A4: 46338 | B4: A棟 | C4: 追肥 | D4: 硝酸鉀 | E4: 13-0-46 | F4: 3.4 | G4: 隨滴灌10分鐘 | H4: 滴灌施肥 | I4: 1.2 | J4: 6.4 | K4: 李大華

Sheet 紀錄_病蟲害防治
A1: 病蟲害監測與防治紀錄
A2: 第4列灰底為填寫範例;依TGAP產銷履歷紀錄需求設計(S2)
A3: 日期 | B3: 棟別/區塊 | C3: 病蟲害/監測項目 | D3: 黏紙計數(隻/張) | E3: 資材名稱(有效成分%與劑型) | F3: 許可證字號 | G3: 稀釋倍數 | H3: 用水量(L) | I3: 安全採收期(天) | J3: 最早可採收日 | K3: 作業人員
A4: 46329 | B4: A棟 | C4: 銀葉粉蝨 | D4: 12 | E4: (請填登記藥劑名稱) | F4: (請填) | G4: 2000 | H4: 200 | I4: 6 | J4: =IF(OR(A4="",I4=""),"",A4+I4) -> 46335 | K4: 李大華
J5: =IF(OR(A5="",I5=""),"",A5+I5)
J6: =IF(OR(A6="",I6=""),"",A6+I6)
J7: =IF(OR(A7="",I7=""),"",A7+I7)
J8: =IF(OR(A8="",I8=""),"",A8+I8)
J9: =IF(OR(A9="",I9=""),"",A9+I9)
J10: =IF(OR(A10="",I10=""),"",A10+I10)
J11: =IF(OR(A11="",I11=""),"",A11+I11)
J12: =IF(OR(A12="",I12=""),"",A12+I12)
J13: =IF(OR(A13="",I13=""),"",A13+I13)
J14: =IF(OR(A14="",I14=""),"",A14+I14)
J15: =IF(OR(A15="",I15=""),"",A15+I15)
J16: =IF(OR(A16="",I16=""),"",A16+I16)
... J63: =IF(OR(A63="",I63=""),"",A63+I63)

Sheet 紀錄_溫濕度
A1: 每日溫濕度與授粉紀錄
A2: 第4列灰底為填寫範例;依TGAP產銷履歷紀錄需求設計(S2)
A3: 日期 | B3: 棟別 | C3: 最高溫(°C) | D3: 最低溫(°C) | E3: 最高RH(%) | F3: 最低RH(%) | G3: 高溫警示 | H3: 通風/遮陰/風扇操作 | I3: 熊蜂咬痕(20朵中有咬痕朵數) | J3: 咬痕率 | K3: 記錄人
A4: 46336 | B4: A棟 | C4: 31 | D4: 19 | E4: 92 | F4: 55 | G4: =IF(C4="","",IF(AND(C4>26,D4>20),"⚠高溫障礙(S4)",IF(E4>=90,"⚠高濕(S13)",""))) -> ⚠高濕(S13) | H4: 07:00開側窗、開循環扇 | I4: 19 | J4: =IF(I4="","",I4/20) -> 0.95 | K4: 王小明
G5: =IF(C5="","",IF(AND(C5>26,D5>20),"⚠高溫障礙(S4)",IF(E5>=90,"⚠高濕(S13)",""))) | J5: =IF(I5="","",I5/20)
G6: =IF(C6="","",IF(AND(C6>26,D6>20),"⚠高溫障礙(S4)",IF(E6>=90,"⚠高濕(S13)",""))) | J6: =IF(I6="","",I6/20)
G7: =IF(C7="","",IF(AND(C7>26,D7>20),"⚠高溫障礙(S4)",IF(E7>=90,"⚠高濕(S13)",""))) | J7: =IF(I7="","",I7/20)
G8: =IF(C8="","",IF(AND(C8>26,D8>20),"⚠高溫障礙(S4)",IF(E8>=90,"⚠高濕(S13)",""))) | J8: =IF(I8="","",I8/20)
G9: =IF(C9="","",IF(AND(C9>26,D9>20),"⚠高溫障礙(S4)",IF(E9>=90,"⚠高濕(S13)",""))) | J9: =IF(I9="","",I9/20)
G10: =IF(C10="","",IF(AND(C10>26,D10>20),"⚠高溫障礙(S4)",IF(E10>=90,"⚠高濕(S13)",""))) | J10: =IF(I10="","",I10/20)
G11: =IF(C11="","",IF(AND(C11>26,D11>20),"⚠高溫障礙(S4)",IF(E11>=90,"⚠高濕(S13)",""))) | J11: =IF(I11="","",I11/20)
G12: =IF(C12="","",IF(AND(C12>26,D12>20),"⚠高溫障礙(S4)",IF(E12>=90,"⚠高濕(S13)",""))) | J12: =IF(I12="","",I12/20)
G13: =IF(C13="","",IF(AND(C13>26,D13>20),"⚠高溫障礙(S4)",IF(E13>=90,"⚠高濕(S13)",""))) | J13: =IF(I13="","",I13/20)
G14: =IF(C14="","",IF(AND(C14>26,D14>20),"⚠高溫障礙(S4)",IF(E14>=90,"⚠高濕(S13)",""))) | J14: =IF(I14="","",I14/20)
G15: =IF(C15="","",IF(AND(C15>26,D15>20),"⚠高溫障礙(S4)",IF(E15>=90,"⚠高濕(S13)",""))) | J15: =IF(I15="","",I15/20)
G16: =IF(C16="","",IF(AND(C16>26,D16>20),"⚠高溫障礙(S4)",IF(E16>=90,"⚠高濕(S13)",""))) | J16: =IF(I16="","",I16/20)
... G63: =IF(C63="","",IF(AND(C63>26,D63>20),"⚠高溫障礙(S4)",IF(E63>=90,"⚠高濕(S13)",""))) | J63: =IF(I63="","",I63/20)

Sheet 紀錄_生長量測
A1: 每週生長量測紀錄(固定10株)
A2: 第4列灰底為填寫範例;依TGAP產銷履歷紀錄需求設計(S2)
A3: 日期 | B3: 定植後週次 | C3: 株號 | D3: 莖徑(mm) | E3: 生長點至開花花序距離(cm) | F3: 本週新開花序數 | G3: 本週著果數 | H3: 植株判斷 | I3: 備註
A4: 46345 | B4: 5 | C4: 1 | D4: 9.5 | E4: 15 | F4: 1 | G4: 6 | H4: =IF(OR(D4="",E4=""),"",IF(E4<13,"偏生殖(花距短)",IF(E4>18,"偏營養(花距長)","平衡"))) -> 平衡
H5: =IF(OR(D5="",E5=""),"",IF(E5<13,"偏生殖(花距短)",IF(E5>18,"偏營養(花距長)","平衡")))
H6: =IF(OR(D6="",E6=""),"",IF(E6<13,"偏生殖(花距短)",IF(E6>18,"偏營養(花距長)","平衡")))
H7: =IF(OR(D7="",E7=""),"",IF(E7<13,"偏生殖(花距短)",IF(E7>18,"偏營養(花距長)","平衡")))
H8: =IF(OR(D8="",E8=""),"",IF(E8<13,"偏生殖(花距短)",IF(E8>18,"偏營養(花距長)","平衡")))
H9: =IF(OR(D9="",E9=""),"",IF(E9<13,"偏生殖(花距短)",IF(E9>18,"偏營養(花距長)","平衡")))
H10: =IF(OR(D10="",E10=""),"",IF(E10<13,"偏生殖(花距短)",IF(E10>18,"偏營養(花距長)","平衡")))
H11: =IF(OR(D11="",E11=""),"",IF(E11<13,"偏生殖(花距短)",IF(E11>18,"偏營養(花距長)","平衡")))
H12: =IF(OR(D12="",E12=""),"",IF(E12<13,"偏生殖(花距短)",IF(E12>18,"偏營養(花距長)","平衡")))
H13: =IF(OR(D13="",E13=""),"",IF(E13<13,"偏生殖(花距短)",IF(E13>18,"偏營養(花距長)","平衡")))
H14: =IF(OR(D14="",E14=""),"",IF(E14<13,"偏生殖(花距短)",IF(E14>18,"偏營養(花距長)","平衡")))
H15: =IF(OR(D15="",E15=""),"",IF(E15<13,"偏生殖(花距短)",IF(E15>18,"偏營養(花距長)","平衡")))
H16: =IF(OR(D16="",E16=""),"",IF(E16<13,"偏生殖(花距短)",IF(E16>18,"偏營養(花距長)","平衡")))
... H123: =IF(OR(D123="",E123=""),"",IF(E123<13,"偏生殖(花距短)",IF(E123>18,"偏營養(花距長)","平衡")))

Sheet 紀錄_採收出貨
A1: 採收與出貨紀錄
A2: 第4列灰底為填寫範例;依TGAP產銷履歷紀錄需求設計(S2)
A3: 採收日期 | B3: 棟別/區塊 | C3: 採收人員 | D3: 採收量(kg) | E3: 糖度(°Brix) | F3: 特級(kg) | G3: 次級(kg) | H3: 格外品/裂果(kg) | I3: 特級比例 | J3: 冷藏溫度(°C) | K3: 出貨對象 | L3: 出貨量(kg)
A4: 46387 | B4: A棟 | C4: 陳阿美 | D4: 85 | E4: 8.2 | F4: 76 | G4: 6 | H4: 3 | I4: =IF(OR(D4="",D4=0),"",F4/D4) -> 0.89411765 | J4: 11 | K4: ○○合作社 | L4: 82
I5: =IF(OR(D5="",D5=0),"",F5/D5)
I6: =IF(OR(D6="",D6=0),"",F6/D6)
I7: =IF(OR(D7="",D7=0),"",F7/D7)
I8: =IF(OR(D8="",D8=0),"",F8/D8)
I9: =IF(OR(D9="",D9=0),"",F9/D9)
I10: =IF(OR(D10="",D10=0),"",F10/D10)
I11: =IF(OR(D11="",D11=0),"",F11/D11)
I12: =IF(OR(D12="",D12=0),"",F12/D12)
I13: =IF(OR(D13="",D13=0),"",F13/D13)
I14: =IF(OR(D14="",D14=0),"",F14/D14)
I15: =IF(OR(D15="",D15=0),"",F15/D15)
I16: =IF(OR(D16="",D16=0),"",F16/D16)
... I63: =IF(OR(D63="",D63=0),"",F63/D63)

Sheet 資料來源
A1: 資料來源
A2: 表中「來源」欄代碼對照;資料彙整於2026年9月
A3: 代碼 | B3: 國內/國外 | C3: 文件名稱 | D3: 網址
A4: S1 | B4: 國內 | C4: 臺南區農業改良場｜小果番茄栽培管理(技術專刊) | D4: https://book.tndais.gov.tw/Brochure/tech96.htm
A5: S2 | B5: 國內 | C5: 產銷履歷 臺灣良好農業規範(TGAP)-蔬菜類-番茄(臺中區農業改良場編撰,2021年版) | D5: https://gazette.nat.gov.tw/EG_FileManager/eguploadpub/eg027026/ch07/type3/gov62/num67/images/BB.pdf
A6: S3 | B6: 國內 | C6: 農業部｜設施番茄之養液土耕栽培技術 | D6: https://www.moa.gov.tw/ws.php?id=19487
A7: S4 | B7: 國內 | C7: 農業知識入口網｜設施小果番茄高溫下生長障礙與調適策略(蔡璿如,農業試驗所) | D7: https://kmweb.moa.gov.tw/knowledgebase.php?func=1&type=12815&id=423553
A8: S5 | B8: 國內 | C8: 臺中區農業改良場研究彙報159:43-56(2023)｜不同鉀肥處理對設施小果番茄生育及品質之影響 | D8: https://www.tcdares.gov.tw/files/tdais/web_structure/13097/A01_1.pdf
A9: S6 | B9: 國內 | C9: 臺南區農業專訊100期｜番茄青枯病防治實務 | D9: https://book.tndais.gov.tw/Magazine/mag100/100-4.pdf
A10: S7 | B10: 國內 | C10: 臺南區農業專訊35期｜番茄嫁接茄子根砧防治土傳病害 | D10: https://book.tndais.gov.tw/Magazine/mag35-1.htm
A11: S8 | B11: 國內 | C11: 臺南區農業改良場｜番茄健康管理生產體系之病蟲害管理(吳雅芳等) | D11: https://kmweb.moa.gov.tw/redirect_files.php?theme=knowledgebase&id=456949
A12: S9 | B12: 國內 | C12: 農傳媒｜掌握番茄栽培關鍵:防治落花落果 | D12: https://www.agriharvest.tw/archives/112232/
A13: S10 | B13: 國內 | C13: 農業知識入口網｜設施栽培養土祕訣 肥培管理防止土壤鹽化(黃瑞彰,臺南場) | D13: https://kmweb.moa.gov.tw/theme_data.php?theme=news&sub_theme=variety&id=55647
A14: S11 | B14: 國內 | C14: 農業部 設施栽培作物蜂授粉技術與效益 | D14: https://www.moa.gov.tw/ws.php?id=2506847
... A25: S22 | B25: 國內 | C25: 農業部動植物防疫檢疫署｜農藥資訊服務網(查詢番茄登記用藥) | D25: https://pesticide.aphia.gov.tw/information/Query/Bug
